<!DOCTYPE html>
<html>
<head>
<meta charset="utf-8">
<title>Panic</title>
</head>
<body>
<p><a href="https://zhuanlan.zhihu.com/p/24546475">原文</a></p>
<div class="title-image"><img src="https://pic3.zhimg.com/v2-89ed7e8f81303d61866c8d9f3039daea_r.jpg" alt=""></div><h2>什么是panic</h2><p>在Rust中，有一类错误，叫做 panic。示例如下：</p><code lang="text">fn main() {
  let x : Option&lt;i32&gt; = None;
  x.unwrap();
}
</code><p>编译，没有错误，执行这段程序，我们可以看到，输出为：</p><code lang="text">thread '&lt;main&gt;' panicked at 'called `Option::unwrap()` on a `None` value', ../src/libcore/option.rs:326
note: Run with `RUST_BACKTRACE=1` for a backtrace.
</code><p>这种情况，我们就引发了一个 panic。在这段代码中，我们调用了Option::unwrap()方法，正是这个方法有可能导致panic。根据提示，我们设置一个环境变量RUST_BACKTRACE=1之后，再执行这个程序，可以看到这个程序在发生panic时候的函数调用栈。<br>执行 RUST_BACKTRACE=1 ./test，结果为：</p><code lang="text">thread 'main' panicked at 'called `Option::unwrap()` on a `None` value', ../src/libcore/option.rs:323
stack backtrace:
 1: 0x10af488f8 - std::sys::backtrace::tracing::imp::write::h6f1d53a70916b90d
 2: 0x10af4a3af - std::panicking::default_hook::{{closure}}::h137e876f7d3b5850
 3: 0x10af49945 - std::panicking::default_hook::h0ac3811ec7cee78c
 4: 0x10af49e96 - std::panicking::rust_panic_with_hook::hc303199e04562edf
 5: 0x10af49d34 - std::panicking::begin_panic::h6ed03353807cf54d
 6: 0x10af49c52 - std::panicking::begin_panic_fmt::hc321cece241bb2f5
 7: 0x10af49bb7 - rust_begin_unwind
 8: 0x10af6f0b0 - core::panicking::panic_fmt::h27224b181f9f037f
 9: 0x10af6efb4 - core::panicking::panic::h53676c30b3bd95eb
10: 0x10af44804 - &lt;core::option::Option&lt;T&gt;&gt;::unwrap::h3478e42c3c27faa3
11: 0x10af44880 - test::main::h8a7a35fa594c0174
12: 0x10af4a96a - __rust_maybe_catch_panic
13: 0x10af49486 - std::rt::lang_start::h538f8960e7644c80
14: 0x10af448b9 - main
</code><p>我们去查一下Option::unwrap()的文档，它是这么说的：</p><code lang="text">Moves the value v out of the Option&lt;T&gt; if it is Some(v).
Panics
  Panics if the self value equals None.
Safety note
  In general, because this function may panic, its use is discouraged.
  Instead, prefer to use pattern matching and handle the None case explicitly.
</code><p>当Option内部的数据是Some时，它可以成功地将内部的数据 move 出来返回。<br>当Option内部的数据是None时，它会发生 panic。panic如果没有被处理，它会导致整个线程甚至进程崩溃。</p><p>在Rust中，正常的错误处理，应该尽量使用 Result 类型。而 Panic 则是作为一种 “fail fast” 机制，处理那种万不得已的情况。</p><p>比如，上面这个例子中的 unwrap 方法，它试图把 Option&lt;int&gt; 转换为 int 类型，当参数是 None 的时候，这个转换是没办法做的，这种时候，就只能使用 panic。所以，一般情况下，用户应该使用 unwrap_or 等这些不会制造 panic 的方法。</p><h2>Panic 实现机制</h2><p>在 Rust 中，Panic 的实现机制有两种方式：unwind 和 abort。</p><ul><li>unwind 方式，在发生 panic 的时候，会一层一层的退出函数调用栈，在此过程中，当前栈内的局部变量还是可以正常析构。</li><li>abort 方式，在发生 panic 的时候，会直接退出整个程序。</li></ul><p>在常见的操作系统上，默认情况下，编译器使用的是 unwind 方式。所以在发生 panic 的时候，我们可以通过一层层的调用栈找到发生 panic 的第一现场，就像前面的例子展示的那样。</p><p>但是，unwind 并不是在所有平台上都能良好支持的。在某些嵌入式系统上，unwind 根本无法实现，或者占用的资源太多。在这种时候，我们可以选择使用 abort 方式实现 panic。</p><p>编译器提供了一个选项，供用户指定 panic 的实现方式。如下所示：</p><code lang="text">rustc -C panic=unwind test.rs
rustc -C panic=abort test.rs
</code><p>读者可以试试上面两个编译命令，做一下对比。可以看到，它们生成的代码，panic时的行为是不一样的，生成的可执行程序大小也不同。</p><p>Rust中，通过 unwind 方式实现的 panic，其内部的实现方式基本与C++的异常是一样的，所以，用户可以在代码中，终止栈展开。示例如下：</p><code lang="text">use std::panic;

fn main() {
  panic::catch_unwind(|| {
    let x : Option&lt;i32&gt; = None;
    x.unwrap();
    println!("interrupted.");
  }).ok();

  println!("continue to execute.");
}
</code><p>编译执行，可见，在 unwrap 语句后面的这条打印语句并未执行。因为在上一条语句中触发了 panic，这个函数调用栈开始销毁。但是我们有一句 catch_unwind 阻止了函数调用栈的继续展开，就像C++里面的 try catch 机制一样。因此，main 方法并没有继续被销毁，最后面那条语句可以正常打印输出。</p><p>如果我们尝试使用 “-C panic=abort” 选项编译上面的代码，可以看到，这个 catch_unwind 起不了什么作用，最后那条语句无法正常打印输出。</p><p>但是，请大家注意，这个 catch_unwind 机制绝对不是设计用于模拟 “try catch” 机制的。<b>请大家永远不要利用这个机制，来做正常的流程控制。</b>它的主要用处在哪里呢，比如下面的这些情况：</p><ol><li><p>在FFI场景下的时候，如果说C语言调用了Rust的函数，在Rust内部出现了panic，如果这个panic在Rust内部没有处理好，直接扔到C代码中去，会导致C语言产生“未定义行为（undefined behavior）”。</p></li><li><p>某些高级抽象机制，需要阻止栈展开。比如线程池，如果一个线程中出现了panic，我们希望只把这个线程关闭，而不至于将整个线程池一起被拖下水。</p></li></ol><h2>Panic Safety</h2><p>C++ 中引入了“异常”这个机制之后，同时，也带入了一个 “异常安全(exception safety)” 的概念。对这个概念不熟悉的读者，可以阅读一下这篇文档：</p><p><a href="http://www.stroustrup.com/except.pdf">http://www.stroustrup.com/except.pdf</a></p><p>异常安全存在4种层次的保证：</p><ol><li><p>No-throw. 这种层次的安全性，保证了所有的异常都在内部正确处理完毕，外部毫无影响。</p></li><li><p>Strong exception safety. 强异常安全保证，可以保证异常发生的时候，所有的状态都可以“回滚”到初始状态，不会导致状态不一致问题。</p></li><li><p>Basic exception safety. 基本异常安全保证，可以保证异常发生的时候，不会导致资源泄漏。</p></li><li><p>No exception safety. 没有任何异常安全保证。</p></li></ol><p>当我们在系统中使用了异常的时候，就一定要想清楚，每个组件应该提供哪种层级的异常安全保证。在Rust中，这个问题同样存在，但是一般叫做 panic safety，说的是同一件事情。</p><p>照例，我们来用代码来示例，“异常安全”问题，会如何影响我们的代码实现。这次，我们用标准库中的一段代码来演示。下面的代码是从 libcollections/vec.rs 中拷贝出来的，extend_with_element 方法目的是在当前 Vec 后面再添加一些元素：</p><code lang="text">fn extend_with_element(&amp;mut self, n: usize, value: T) {
  self.reserve(n);

  unsafe {
    let mut ptr = self.as_mut_ptr().offset(self.len() as isize);
    let mut local_len = SetLenOnDrop::new(&amp;mut self.len);

    for _ in 1..n {
      ptr::write(ptr, value.clone());
      ptr = ptr.offset(1);
      local_len.increment_len(1);
    }

    if n &gt; 0 {
      ptr::write(ptr, value);
      local_len.increment_len(1);
    }
  }
}
</code><p>这段代码实现的稍微有点复杂。我们可以先不考虑标准实现，想想如果自己来实现，会怎么做。首先，要让 Vec 扩容，至少剩余空间可以装得下 n 个 T 类型变量。然后，使用一个循环，将 value 复制 n 份，插入到数组尾部即可。代码基本上像这个样子：</p><code lang="text">fn extend_with_element(&amp;mut self, n: usize, value: T) {
  self.reserve(n);

  unsafe {
    set_len(self.len() + n);

    let mut ptr = self.as_mut_ptr().offset(self.len() as isize);

    for _ in 1..n+1 {
      ptr::write(ptr, value.clone());
      ptr = ptr.offset(1);
    }
  }
}
</code><p>对比一下，我们的实现和标准库中的实现方式，可以看到，首先，性能方面可以优化一下，因为我们总共需要 n 个 T 类型变量，而最开始我们就已经有了一个，所以其实应该可以只复制 n - 1 次即可。其次，区别比较大的是那个 SetLenOnDrop 变量。</p><p>为什么明明可以直接在一个方法里写完的代码，还要引入一个新的类型呢？原因就在于 panic safe 问题。注意我们这里调用了 T 类型的 clone 方法。T 是一个泛型参数，谁能保证 clone 方法不会产生 panic？没有谁能保证，我们只能尽可能让 clone 发生 panic 的时候，Vec 的状态不会乱掉。</p><p>如果我们先改变了 Vec 的长度，然后调用 clone 方法，并发生了异常，那么 Vec 就处于一个非常糟糕的 “内存不安全” 境地。因为扩容后的空间已经被 Vec 认为是它的正常成员，但是它们并没有被正常初始化。如果这个 panic 被 catch 住了，并且继续使用这个 Vec 变量，那么什么野指针空指针，都有可能出现了。</p><p>如果我们先执行数据复制操作，最后再执行 set_len 方法，改变 Vec 的长度，这么做至少可以保证 Vec 中的数据都是被正确初始化好的数据。但是，如果前面有几个 clone 的执行是正常的，后面才发生 panic，那么 set_len 就不会被调用，Vec 维持原先的长度不变，前面拷贝的内容就浪费了。</p><p>所以，标准库的实现，利用了 RAII 机制，即便在 clone 的时候发生了 panic，这个 SetLenOnDrop 类型的局部变量的析构函数依然会正确执行，并在析构函数中，将 Vec 的长度设置为正确的值。这就是为什么在循环中，每次都要去更新一下当前拷贝的数量值。</p><p>大家可以去翻一下标准库中的代码，有大量的类似的模式存在，都是因为需要考虑 panic safe 问题。Rust 的标准库保证了，即便发生了 panic，也不会产生 “内存不安全” 和 “线程不安全” 的情况。</p><p>更复杂的情况是 Vec::drain 方法。这个方法把一个区间的所有元素从原先的 Vec 中取出来，而且可以被迭代器使用。使用方法如下：</p><code lang="text">fn main() {
    let mut v = vec![1,2,3,4,5];
    for i in v.drain(1..3) {
        println!("drain item {}", i);
    }
    println!("items left {:?}", v);
}
</code><p>执行结果为：</p><code lang="text">drain item 2
drain item 3
items left [1, 4, 5]
</code><p>我们可以看到，在 drain 执行完毕后，原先的 Vec 中后面的元素应该往前移动，填充空余出来的空间。此事是在 Drain 迭代器的析构函数中完成的。即便万一在遍历 drain 的过程中，发生了 panic，它的析构函数依然可以正常调用，Vec 不会包含被破坏掉的数据。它依然是异常安全的。但是，这个设计，有一个缺陷，那就是当它碰上“内存泄漏”的时候，会“放大泄漏”。示例如下：</p><code lang="text">fn main() {
  let mut v = vec![1,2,3,4,5];
  {
    let drain = v.drain(1..3);
    std::mem::forget(drain);
  }
  println!("items left {:?}", v);
}
</code><p>执行结果为：</p><code lang="text">items left [1]
</code><p>forget 函数可以阻止一个对象的析构函数调用。前面我们已经说过了，为什么 forget 函数是“安全”的。Rust中，一个对象的析构函数，是有可能不被执行的。而我们的许多逻辑，实际上是依赖析构函数的。这就是为什么，标准库中，drain 方法调用的时候，先把 Vec 的长度设置为 drain 区间的起始点的原因。如果不预先做这个设置，而是先把数据移动出来，再等析构函数来给 Vec 设置正确的长度，是有风险的，万一这个析构函数没有执行，就制造出来了内存不安全。所以，drain 方法只能保守的先把 Vec 长度设置为很小的一个值，迭代器析构的时候，再设置回正确的长度。这样才能保证“异常安全”。而这样设计，在某些时候，也导致了“泄漏放大”效应。</p><p>在Rust中，什么情况下，panic会导致bug呢？这种情况的产生需要两个条件：</p><ol><li>panic导致了数据结构内部的状态错误；</li><li>这个错误的状态会在以后被观测到。</li></ol><p>在 unsafe 代码中，这种情况非常容易出现。所以，在写 unsafe 代码的时候，需要对这种情况非常敏感小心，一不小心，可能因为这个原因，制造出“内存不安全”。</p><p>在不用 unsafe 的情况下，Panic Safety 是基本有保障的。考虑一种场景，假如我们有两个数据结构，我们希望每次在更新其中一个的时候，也要对另外一个同步更新，如果不一致就会有问题。万一更新了其中一个，发生了 panic，第二个没有正常更新怎么办，代码示例如下：</p><code lang="text">use std::panic;

fn main() {
  let mut x : Vec&lt;i32&gt; = vec![1];
  let mut y : Vec&lt;i32&gt; = vec![2];
  panic::catch_unwind(|| {
    x.push(10);
    panic!("user panic");
    y.push(100);
  }).ok();

  println!("Observe corruptted data. {:?} {:?}", x, y);
}
</code><p>这里我们必须使用 catch_unwind 来阻止栈展开，否则这两个数据结构就一起被销毁掉了，无法观测到panic引发的错误状态。编译可见，这段代码是无法编译通过的，错误如下：</p><code lang="text">error[E0277]: the trait bound `&amp;mut std::vec::Vec&lt;i32&gt;: std::panic::UnwindSafe` is not satisfied
</code><p>这是什么原因呢？因为 catch_unwind 的签名是这样的：</p><code lang="text">pub fn catch_unwind&lt;F: FnOnce() -&gt; R + UnwindSafe, R&gt;(f: F) -&gt; Result&lt;R&gt;
</code><p>它要求闭包参数满足 UnwindSafe 条件，而标准库中早就标记好了 &amp;mut 型指针是不满足 UnwindSafe trait 的。有些类型，天生就不适合在 catch_unwind 的外部和内部同时存在。</p><p>有了这个约束条件，被 panic 破坏掉的数据结构，被外部继续观测、使用的几率就小了许多。</p><p>当然，编译器是永远不知道用户的真实意图的，可能某些场景下，用户就是要这么写，而且不认为这些数据结构是“被破坏”的状态，怎么修复上面这个编译错误呢？示例如下：</p><code lang="text">use std::panic;
use std::panic::AssertUnwindSafe;

fn main() {
  let mut x : Vec&lt;i32&gt; = vec![1];
  let mut y : Vec&lt;i32&gt; = vec![2];
  panic::catch_unwind(AssertUnwindSafe(|| {
    x.push(10);
    panic!("user panic");
    y.push(100);
  })).ok();

  println!("Observe corruptted data. {:?} {:?}", x, y);
}
</code><p>我们可以用 AssertUnwindSafe 把这个闭包包一层，就可以强制突破编译器的限制了。我们也可以单独为某个变量来包一层，一样的效果。这个设计，至少能保证，catch_unwind 可能造成的风险是显式标记出来的。</p><p>同理，在多线程情况下，也有类似的问题。比如，我们把前面经常拿来示例的多线程修改全局变量的程序改改，在其中某个线程中，制造一个 panic：</p><code lang="text">use std::sync::Arc;
use std::sync::Mutex;
use std::thread;

const COUNT: u32 = 1000000;

fn main() {
    let global = Arc::new(Mutex::new(0));

    let clone1 = global.clone();
    let thread1 = thread::spawn(move|| {
        for _ in 0..COUNT {
            match clone1.lock(){
                Ok(mut value) =&gt; *value +=1,
                Err(poisoned) =&gt; {
                    let mut value = poisoned.into_inner();
                    *value += 1;
                }
            }
        }
    });

    let clone2 = global.clone();
    let thread2 = thread::spawn(move|| {
        for _ in 0..COUNT {
            let mut value = clone2.lock().unwrap();
            *value -= 1;
            if *value &lt; 100000 {
                println!("make a panic");
                panic!("");
            }
        }
    });

    thread1.join().ok();
    thread2.join().ok();
    println!("final value: {:?}", global);
}
</code><p>在 thread2 中，达到某个条件的情况下，会发生 panic。这个 panic 是在 Mutex 锁定的状态下发生的，这种时候，标准库会将 Mutex 设置为一个特殊的称为 poisoned 状态。处在这个状态下的 Mutex，再次调用 lock，会返回 Err 状态。它里面依然包含了原先的数据，只不过用户需要显式调用 into_inner 才能使用它。通过这种方式，防止了用户在不小心的情况下，产生异常不安全的风险。</p><h2>总结</h2><p>Rust 语言是跟 C++ 非常相似的一门语言。它们的定位相似，目标一致，都没有 GC，都面向底层硬件，都希望提供比较好的高级抽象能力，都对性能有非常高的要求。而这也意味着，在许多情况下，它们会碰到同样的问题，有类似的设计思路。</p><p>Rust 跟 C++ 最大的区别在于，它彻底摆脱了 C/C++ 遗留下来的“前向兼容性”包袱，可以大刀阔斧地引入一些在其它语言中早已被证明的优秀设计。Rust 在保持底层定位的同时，把关注点主要放在了“安全性”这个问题上。除了前面介绍的“内存安全”、“线程安全”，其实在“异常安全”方面的设计也非常不错，只是比较少用于拿出来宣传而已，毕竟只有 C++ 是跟 Rust 遭遇了类似的问题，其它自带 GC 的语言，在这个问题上基本没什么需要特别关注的。相比于 C++ 的异常安全概念，Rust 并没有什么好办法把它完全处理好。但是，至少，它通过一系列设计，将这个问题基本控制在了 unsafe 代码中。在 safe 代码部分，编译器会将可能发生异常安全的部分提示出来，让用户显式处理，用户基本不会由于不小心被这个问题“坑”到。</p><p>虽然 Rust 抛弃了“兼容性”这样一个巨大的负担，但是，并不意味着设计这样一门语言是件轻松的事情。在“系统级”编程语言的这个紧箍咒之下，很多看似简单的方面都需要权衡和妥协。比如，“易用性”、“简洁性”总是永远排在“安全性”、“性能”这样的目标后面。这也注定了 Rust 不可能成为一门大众化的，被广泛使用的语言。</p><br><p>本文同步发布在微信公众号：<b>Rust编程</b>，欢迎关注。</p><br>​
<script async defer="defer" src="https://www.googletagmanager.com/gtag/js?id=UA-7909075-5"></script>
<script>
window.dataLayer = window.dataLayer || [];
function gtag(){ dataLayer.push(arguments); }
gtag('js', new Date());
gtag('config', 'UA-7909075-5');
</script>
<script>
var _hmt = _hmt || [];
</script>
<script async defer="defer" src="https://hm.baidu.com/hm.js?e3d40295e416616ddc21287da9646d31"></script>
</body>
</html>
